<testsuite errors="10" failures="12" name="Django Project Tests" skips="0" tests="71" time="13.688"><testcase classname="api.tests.test_api_anthologies.AnthologyApiTest" name="test_get_request_has_200_status_code" time="0.279576" /><testcase classname="api.tests.test_api_anthologies.AnthologyApiTest" name="test_get_request_with_id_has_200_status_code" time="0.161164" /><testcase classname="api.tests.test_api_anthologies.AnthologyApiTest" name="test_get_request_with_non_existent_id_has_404_status_code" time="0.191360" /><testcase classname="api.tests.test_api_anthologies.AnthologyApiTest" name="test_number_of_items_are_equal" time="0.185123" /><testcase classname="api.tests.test_api_anthologies.AnthologyApiTest" name="test_random_text_as_parameter_gives_400_status_code" time="0.183333"><failure message="200 != 400" type="builtins.AssertionError">Traceback (most recent call last):
  File "/tE-backend/tRecorderApi/api/tests/test_api_anthologies.py", line 39, in test_random_text_as_parameter_gives_400_status_code
    self.assertEqual(response.status_code, status.HTTP_400_BAD_REQUEST)
AssertionError: 200 != 400
</failure></testcase><testcase classname="api.tests.test_api_anthologies.AnthologyApiTest" name="test_slug_equals_ot_as_parameter_has_len_one" time="0.140184"><failure message="0 != 1" type="builtins.AssertionError">Traceback (most recent call last):
  File "/tE-backend/tRecorderApi/api/tests/test_api_anthologies.py", line 43, in test_slug_equals_ot_as_parameter_has_len_one
    self.assertEqual(len(response.data), 1)
AssertionError: 0 != 1
</failure></testcase><testcase classname="api.tests.test_api_books.BookApiTest" name="test_get_request_has_200_status_code" time="0.243191" /><testcase classname="api.tests.test_api_books.BookApiTest" name="test_get_request_with_id_has_200_status_code" time="0.201320" /><testcase classname="api.tests.test_api_books.BookApiTest" name="test_get_request_with_non_existent_id_has_404_status_code" time="0.182679" /><testcase classname="api.tests.test_api_books.BookApiTest" name="test_number_of_items_are_equal" time="0.155510" /><testcase classname="api.tests.test_api_books.BookApiTest" name="test_random_text_as_parameter_gives_400_status_code" time="0.176620"><failure message="200 != 400" type="builtins.AssertionError">Traceback (most recent call last):
  File "/tE-backend/tRecorderApi/api/tests/test_api_books.py", line 40, in test_random_text_as_parameter_gives_400_status_code
    self.assertEqual(response.status_code, status.HTTP_400_BAD_REQUEST)
AssertionError: 200 != 400
</failure></testcase><testcase classname="api.tests.test_api_books.BookApiTest" name="test_slug_equals_en_x_demo_as_parameter_has_len_one" time="0.193099" /><testcase classname="api.tests.test_api_chapters.ChapterApiTest" name="test_get_request_has_200_status_code" time="0.355436" /><testcase classname="api.tests.test_api_chapters.ChapterApiTest" name="test_get_request_with_id_has_200_status_code" time="0.221355" /><testcase classname="api.tests.test_api_chapters.ChapterApiTest" name="test_get_request_with_non_existent_id_has_404_status_code" time="0.150686" /><testcase classname="api.tests.test_api_chapters.ChapterApiTest" name="test_number_of_items_are_equal" time="0.280849" /><testcase classname="api.tests.test_api_chapters.ChapterApiTest" name="test_random_text_as_parameter_gives_400_status_code" time="0.218120"><failure message="200 != 400" type="builtins.AssertionError">Traceback (most recent call last):
  File "/tE-backend/tRecorderApi/api/tests/test_api_chapters.py", line 46, in test_random_text_as_parameter_gives_400_status_code
    self.assertEqual(response.status_code, status.HTTP_400_BAD_REQUEST)
AssertionError: 200 != 400
</failure></testcase><testcase classname="api.tests.test_api_chapters.ChapterApiTest" name="test_response_contains_project" time="0.503586"><error message="'ReturnList' object has no attribute 'status_code'" type="builtins.AttributeError">Traceback (most recent call last):
  File "/tE-backend/tRecorderApi/api/tests/test_api_chapters.py", line 50, in test_response_contains_project
    self.assertContains(response.data, self.project)
  File "/usr/local/lib/python3.6/site-packages/django/test/testcases.py", line 385, in assertContains
    response, text, status_code, msg_prefix, html)
  File "/usr/local/lib/python3.6/site-packages/django/test/testcases.py", line 355, in _assert_contains
    response.status_code, status_code,
AttributeError: 'ReturnList' object has no attribute 'status_code'
</error></testcase><testcase classname="api.tests.test_api_chunks.ChunkApiTest" name="test_get_request_has_200_status_code" time="0.230507" /><testcase classname="api.tests.test_api_chunks.ChunkApiTest" name="test_get_request_with_id_has_200_status_code" time="0.178867" /><testcase classname="api.tests.test_api_chunks.ChunkApiTest" name="test_get_request_with_non_existent_id_has_404_status_code" time="0.223605" /><testcase classname="api.tests.test_api_chunks.ChunkApiTest" name="test_number_of_items_are_equal" time="0.213764" /><testcase classname="api.tests.test_api_chunks.ChunkApiTest" name="test_random_text_as_parameter_gives_400_status_code" time="0.190761"><failure message="200 != 400" type="builtins.AssertionError">Traceback (most recent call last):
  File "/tE-backend/tRecorderApi/api/tests/test_api_chunks.py", line 50, in test_random_text_as_parameter_gives_400_status_code
    self.assertEqual(response.status_code, status.HTTP_400_BAD_REQUEST)
AssertionError: 200 != 400
</failure></testcase><testcase classname="api.tests.test_api_chunks.ChunkApiTest" name="test_response_contains_project" time="0.201339"><error message="'ReturnList' object has no attribute 'status_code'" type="builtins.AttributeError">Traceback (most recent call last):
  File "/tE-backend/tRecorderApi/api/tests/test_api_chunks.py", line 54, in test_response_contains_project
    self.assertContains(response.data, self.project)
  File "/usr/local/lib/python3.6/site-packages/django/test/testcases.py", line 385, in assertContains
    response, text, status_code, msg_prefix, html)
  File "/usr/local/lib/python3.6/site-packages/django/test/testcases.py", line 355, in _assert_contains
    response.status_code, status_code,
AttributeError: 'ReturnList' object has no attribute 'status_code'
</error></testcase><testcase classname="api.tests.test_api_comments.CommentApiTest" name="test_get_request_has_200_status_code" time="0.182905" /><testcase classname="api.tests.test_api_comments.CommentApiTest" name="test_get_request_with_id_has_200_status_code" time="0.202431" /><testcase classname="api.tests.test_api_comments.CommentApiTest" name="test_get_request_with_non_existent_id_has_404_status_code" time="0.177701" /><testcase classname="api.tests.test_api_comments.CommentApiTest" name="test_number_of_items_are_equal" time="0.202940" /><testcase classname="api.tests.test_api_comments.CommentApiTest" name="test_random_text_as_parameter_gives_400_status_code" time="0.158990"><failure message="200 != 400" type="builtins.AssertionError">Traceback (most recent call last):
  File "/tE-backend/tRecorderApi/api/tests/test_api_comments.py", line 50, in test_random_text_as_parameter_gives_400_status_code
    self.assertEqual(response.status_code, status.HTTP_400_BAD_REQUEST)
AssertionError: 200 != 400
</failure></testcase><testcase classname="api.tests.test_api_comments.CommentApiTest" name="test_response_contains_project" time="0.192777"><error message="'ReturnList' object has no attribute 'status_code'" type="builtins.AttributeError">Traceback (most recent call last):
  File "/tE-backend/tRecorderApi/api/tests/test_api_comments.py", line 54, in test_response_contains_project
    self.assertContains(response.data, self.project)
  File "/usr/local/lib/python3.6/site-packages/django/test/testcases.py", line 385, in assertContains
    response, text, status_code, msg_prefix, html)
  File "/usr/local/lib/python3.6/site-packages/django/test/testcases.py", line 355, in _assert_contains
    response.status_code, status_code,
AttributeError: 'ReturnList' object has no attribute 'status_code'
</error></testcase><testcase classname="api.tests.test_api_languages.LanguageApiTest" name="test_get_request_has_200_status_code" time="0.167357" /><testcase classname="api.tests.test_api_languages.LanguageApiTest" name="test_get_request_with_id_has_200_status_code" time="0.241736" /><testcase classname="api.tests.test_api_languages.LanguageApiTest" name="test_get_request_with_non_existent_id_has_404_status_code" time="0.171096" /><testcase classname="api.tests.test_api_languages.LanguageApiTest" name="test_number_of_items_are_equal" time="0.256567" /><testcase classname="api.tests.test_api_languages.LanguageApiTest" name="test_random_text_as_parameter_gives_400_status_code" time="0.168067"><failure message="200 != 400" type="builtins.AssertionError">Traceback (most recent call last):
  File "/tE-backend/tRecorderApi/api/tests/test_api_languages.py", line 39, in test_random_text_as_parameter_gives_400_status_code
    self.assertEqual(response.status_code, status.HTTP_400_BAD_REQUEST)
AssertionError: 200 != 400
</failure></testcase><testcase classname="api.tests.test_api_languages.LanguageApiTest" name="test_slug_equals_en_x_demo_as_parameter_has_len_one" time="0.146159" /><testcase classname="api.tests.test_api_modes.ModesApiTest" name="test_get_request_has_200_status_code" time="0.171309" /><testcase classname="api.tests.test_api_modes.ModesApiTest" name="test_get_request_with_id_has_200_status_code" time="0.223120" /><testcase classname="api.tests.test_api_modes.ModesApiTest" name="test_get_request_with_non_existent_id_has_404_status_code" time="0.178742" /><testcase classname="api.tests.test_api_modes.ModesApiTest" name="test_number_of_items_are_equal" time="0.210582" /><testcase classname="api.tests.test_api_modes.ModesApiTest" name="test_random_text_as_parameter_gives_400_status_code" time="0.156598"><failure message="200 != 400" type="builtins.AssertionError">Traceback (most recent call last):
  File "/tE-backend/tRecorderApi/api/tests/test_api_modes.py", line 39, in test_random_text_as_parameter_gives_400_status_code
    self.assertEqual(response.status_code, status.HTTP_400_BAD_REQUEST)
AssertionError: 200 != 400
</failure></testcase><testcase classname="api.tests.test_api_modes.ModesApiTest" name="test_slug_equals_en_x_demo_as_parameter_has_len_one" time="0.170460" /><testcase classname="api.tests.test_api_projects.ProjectsApiTest" name="test_get_request_has_200_status_code" time="0.282691" /><testcase classname="api.tests.test_api_projects.ProjectsApiTest" name="test_get_request_with_id_has_200_status_code" time="0.269014" /><testcase classname="api.tests.test_api_projects.ProjectsApiTest" name="test_get_request_with_non_existent_id_has_404_status_code" time="0.212834" /><testcase classname="api.tests.test_api_projects.ProjectsApiTest" name="test_number_of_items_are_equal" time="0.247381" /><testcase classname="api.tests.test_api_projects.ProjectsApiTest" name="test_random_text_as_parameter_gives_400_status_code" time="0.168141"><failure message="200 != 400" type="builtins.AssertionError">Traceback (most recent call last):
  File "/tE-backend/tRecorderApi/api/tests/test_api_projects.py", line 46, in test_random_text_as_parameter_gives_400_status_code
    self.assertEqual(response.status_code, status.HTTP_400_BAD_REQUEST)
AssertionError: 200 != 400
</failure></testcase><testcase classname="api.tests.test_api_projects.ProjectsApiTest" name="test_slug_equals_en_x_demo_as_parameter_has_len_one" time="0.199975"><failure message="0 != 1" type="builtins.AssertionError">Traceback (most recent call last):
  File "/tE-backend/tRecorderApi/api/tests/test_api_projects.py", line 50, in test_slug_equals_en_x_demo_as_parameter_has_len_one
    self.assertEqual(len(response.data), 1)
AssertionError: 0 != 1
</failure></testcase><testcase classname="api.tests.test_api_takes.TakesApiTest" name="test_get_request_has_200_status_code" time="0.189426" /><testcase classname="api.tests.test_api_takes.TakesApiTest" name="test_get_request_with_id_has_200_status_code" time="0.294739" /><testcase classname="api.tests.test_api_takes.TakesApiTest" name="test_get_request_with_non_existent_id_has_404_status_code" time="0.226791" /><testcase classname="api.tests.test_api_takes.TakesApiTest" name="test_number_of_items_are_equal" time="0.188428" /><testcase classname="api.tests.test_api_takes.TakesApiTest" name="test_published_is_updated" time="0.200153" /><testcase classname="api.tests.test_api_takes.TakesApiTest" name="test_random_text_as_parameter_gives_400_status_code" time="0.209917"><failure message="200 != 400" type="builtins.AssertionError">Traceback (most recent call last):
  File "/tE-backend/tRecorderApi/api/tests/test_api_takes.py", line 51, in test_random_text_as_parameter_gives_400_status_code
    self.assertEqual(response.status_code, status.HTTP_400_BAD_REQUEST)
AssertionError: 200 != 400
</failure></testcase><testcase classname="api.tests.test_api_takes.TakesApiTest" name="test_rating_is_updated" time="0.208786" /><testcase classname="api.tests.test_api_versions.VersionApiTest" name="test_get_request_has_200_status_code" time="0.211093" /><testcase classname="api.tests.test_api_versions.VersionApiTest" name="test_get_request_with_id_has_200_status_code" time="0.187814" /><testcase classname="api.tests.test_api_versions.VersionApiTest" name="test_get_request_with_non_existent_id_has_404_status_code" time="0.221970" /><testcase classname="api.tests.test_api_versions.VersionApiTest" name="test_number_of_items_are_equal" time="0.161738" /><testcase classname="api.tests.test_api_versions.VersionApiTest" name="test_random_text_as_parameter_gives_400_status_code" time="0.159767"><failure message="200 != 400" type="builtins.AssertionError">Traceback (most recent call last):
  File "/tE-backend/tRecorderApi/api/tests/test_api_versions.py", line 39, in test_random_text_as_parameter_gives_400_status_code
    self.assertEqual(response.status_code, status.HTTP_400_BAD_REQUEST)
AssertionError: 200 != 400
</failure></testcase><testcase classname="api.tests.test_api_versions.VersionApiTest" name="test_slug_equals_en_x_demo_as_parameter_has_len_one" time="0.230372" /><testcase classname="api.tests.test_api_zip.ZipApiTest" name="test_download_zip_mp3_has_status_200_OK" time="0.300935"><error message="[Errno 2] No such file or directory: '/tE-backend/tRecorderApi/api/tests/test_files/zip/abc.wav'" type="builtins.FileNotFoundError">Traceback (most recent call last):
  File "/tE-backend/tRecorderApi/api/tests/test_api_zip.py", line 31, in test_download_zip_mp3_has_status_200_OK
    response = self.client.get('/api/zip/?id=1&amp;file_format=mp3/')
  File "/usr/local/lib/python3.6/site-packages/rest_framework/test.py", line 291, in get
    response = super(APIClient, self).get(path, data=data, **extra)
  File "/usr/local/lib/python3.6/site-packages/rest_framework/test.py", line 208, in get
    return self.generic('GET', path, **r)
  File "/usr/local/lib/python3.6/site-packages/rest_framework/test.py", line 237, in generic
    method, path, data, content_type, secure, **extra)
  File "/usr/local/lib/python3.6/site-packages/django/test/client.py", line 416, in generic
    return self.request(**r)
  File "/usr/local/lib/python3.6/site-packages/rest_framework/test.py", line 288, in request
    return super(APIClient, self).request(**kwargs)
  File "/usr/local/lib/python3.6/site-packages/rest_framework/test.py", line 240, in request
    request = super(APIRequestFactory, self).request(**kwargs)
  File "/usr/local/lib/python3.6/site-packages/django/test/client.py", line 501, in request
    six.reraise(*exc_info)
  File "/usr/local/lib/python3.6/site-packages/django/utils/six.py", line 686, in reraise
    raise value
  File "/usr/local/lib/python3.6/site-packages/django/core/handlers/exception.py", line 41, in inner
    response = get_response(request)
  File "/usr/local/lib/python3.6/site-packages/django/core/handlers/base.py", line 187, in _get_response
    response = self.process_exception_by_middleware(e, request)
  File "/usr/local/lib/python3.6/site-packages/django/core/handlers/base.py", line 185, in _get_response
    response = wrapped_callback(request, *callback_args, **callback_kwargs)
  File "/usr/local/lib/python3.6/site-packages/django/views/decorators/csrf.py", line 58, in wrapped_view
    return view_func(*args, **kwargs)
  File "/usr/local/lib/python3.6/site-packages/rest_framework/viewsets.py", line 95, in view
    return self.dispatch(request, *args, **kwargs)
  File "/usr/local/lib/python3.6/site-packages/rest_framework/views.py", line 494, in dispatch
    response = self.handle_exception(exc)
  File "/usr/local/lib/python3.6/site-packages/rest_framework/views.py", line 454, in handle_exception
    self.raise_uncaught_exception(exc)
  File "/usr/local/lib/python3.6/site-packages/rest_framework/views.py", line 491, in dispatch
    response = handler(request, *args, **kwargs)
  File "/tE-backend/tRecorderApi/api/views/zip.py", line 58, in list
    zipped_file_location = zip_it.download(project_name, take_location_list, root_dir, file_format)
  File "/tE-backend/tRecorderApi/api/file_transfer/Download.py", line 9, in download
    self.file_utility.copy_files_from_src_to_dest(location_list)
  File "/tE-backend/tRecorderApi/api/file_transfer/FileUtility.py", line 174, in copy_files_from_src_to_dest
    shutil.copy2(location["src"], location["dst"])
  File "/usr/local/lib/python3.6/shutil.py", line 257, in copy2
    copyfile(src, dst, follow_symlinks=follow_symlinks)
  File "/usr/local/lib/python3.6/shutil.py", line 120, in copyfile
    with open(src, 'rb') as fsrc:
FileNotFoundError: [Errno 2] No such file or directory: '/tE-backend/tRecorderApi/api/tests/test_files/zip/abc.wav'
</error></testcase><testcase classname="api.tests.test_api_zip.ZipApiTest" name="test_download_zip_mp3_with_invalid_id_has_status_404_Not_Found" time="0.208251"><error message="list index out of range" type="builtins.IndexError">Traceback (most recent call last):
  File "/tE-backend/tRecorderApi/api/tests/test_api_zip.py", line 37, in test_download_zip_mp3_with_invalid_id_has_status_404_Not_Found
    response = self.client.get('/api/zip/?id=2&amp;file_format=mp3/')
  File "/usr/local/lib/python3.6/site-packages/rest_framework/test.py", line 291, in get
    response = super(APIClient, self).get(path, data=data, **extra)
  File "/usr/local/lib/python3.6/site-packages/rest_framework/test.py", line 208, in get
    return self.generic('GET', path, **r)
  File "/usr/local/lib/python3.6/site-packages/rest_framework/test.py", line 237, in generic
    method, path, data, content_type, secure, **extra)
  File "/usr/local/lib/python3.6/site-packages/django/test/client.py", line 416, in generic
    return self.request(**r)
  File "/usr/local/lib/python3.6/site-packages/rest_framework/test.py", line 288, in request
    return super(APIClient, self).request(**kwargs)
  File "/usr/local/lib/python3.6/site-packages/rest_framework/test.py", line 240, in request
    request = super(APIRequestFactory, self).request(**kwargs)
  File "/usr/local/lib/python3.6/site-packages/django/test/client.py", line 501, in request
    six.reraise(*exc_info)
  File "/usr/local/lib/python3.6/site-packages/django/utils/six.py", line 686, in reraise
    raise value
  File "/usr/local/lib/python3.6/site-packages/django/core/handlers/exception.py", line 41, in inner
    response = get_response(request)
  File "/usr/local/lib/python3.6/site-packages/django/core/handlers/base.py", line 187, in _get_response
    response = self.process_exception_by_middleware(e, request)
  File "/usr/local/lib/python3.6/site-packages/django/core/handlers/base.py", line 185, in _get_response
    response = wrapped_callback(request, *callback_args, **callback_kwargs)
  File "/usr/local/lib/python3.6/site-packages/django/views/decorators/csrf.py", line 58, in wrapped_view
    return view_func(*args, **kwargs)
  File "/usr/local/lib/python3.6/site-packages/rest_framework/viewsets.py", line 95, in view
    return self.dispatch(request, *args, **kwargs)
  File "/usr/local/lib/python3.6/site-packages/rest_framework/views.py", line 494, in dispatch
    response = self.handle_exception(exc)
  File "/usr/local/lib/python3.6/site-packages/rest_framework/views.py", line 454, in handle_exception
    self.raise_uncaught_exception(exc)
  File "/usr/local/lib/python3.6/site-packages/rest_framework/views.py", line 491, in dispatch
    response = handler(request, *args, **kwargs)
  File "/tE-backend/tRecorderApi/api/views/zip.py", line 42, in list
    language_slug = projects[0].chunk.chapter.project.language.slug
  File "/usr/local/lib/python3.6/site-packages/django/db/models/query.py", line 289, in __getitem__
    return list(qs)[0]
IndexError: list index out of range
</error></testcase><testcase classname="api.tests.tests_books.IntegrationBookTests" name="test_get_book" time="0.002883"><error message="type object 'Book' has no attribute 'get_books'" type="builtins.AttributeError">Traceback (most recent call last):
  File "/tE-backend/tRecorderApi/api/tests/tests_books.py", line 24, in test_get_book
    get_book = Book.get_books(book_filter)
AttributeError: type object 'Book' has no attribute 'get_books'
</error></testcase><testcase classname="api.tests.tests_get_projects.GetProjectsTestCases" name="test_get_minimum_checked_level" time="0.013192" /><testcase classname="api.tests.tests_get_projects.GetProjectsTestCases" name="test_get_percentage_function" time="0.019947"><error message="type object 'Project' has no attribute 'get_percentage_completed'" type="builtins.AttributeError">Traceback (most recent call last):
  File "/tE-backend/tRecorderApi/api/tests/tests_get_projects.py", line 83, in test_get_percentage_function
    percentage = Project.get_percentage_completed(chunks_done, total_chunks)
AttributeError: type object 'Project' has no attribute 'get_percentage_completed'
</error></testcase><testcase classname="api.tests.tests_get_projects.GetProjectsTestCases" name="test_get_total_chunks" time="0.014499" /><testcase classname="api.tests.tests_get_projects.GetProjectsTestCases" name="test_keys_in_project" time="0.012348"><error message="type object 'Project' has no attribute 'get_projects'" type="builtins.AttributeError">Traceback (most recent call last):
  File "/tE-backend/tRecorderApi/api/tests/tests_get_projects.py", line 66, in test_keys_in_project
    projects = Project.get_projects(get_projects)
AttributeError: type object 'Project' has no attribute 'get_projects'
</error></testcase><testcase classname="api.tests.tests_upload.UploadTestCases" name="test_create_root_directory" time="0.024981" /><testcase classname="api.tests.tests_upload.UploadTestCases" name="test_throws_exception" time="0.002310"><error message="[Errno 2] No such file or directory: '/tE-backend/tRecorderApi/api/tests/test_files/test/manifest.json'" type="builtins.FileNotFoundError">Traceback (most recent call last):
  File "/tE-backend/tRecorderApi/api/tests/tests_upload.py", line 57, in test_throws_exception
    self.assertRaises(Exception, fl.import_project(file_to_upload))
  File "/tE-backend/tRecorderApi/api/file_transfer/FileUtility.py", line 51, in import_project
    project_manifest = self.open_manifest_file(directory)
  File "/tE-backend/tRecorderApi/api/file_transfer/FileUtility.py", line 101, in open_manifest_file
    manifest = json.load(open(manifest_path))
FileNotFoundError: [Errno 2] No such file or directory: '/tE-backend/tRecorderApi/api/tests/test_files/test/manifest.json'
</error></testcase><testcase classname="api.tests.tests_upload.UploadTestCases" name="test_upload_zip_" time="0.148387"><error message="Object of type 'Upload' is not JSON serializable" type="kombu.exceptions.EncodeError">Traceback (most recent call last):
  File "/usr/local/lib/python3.6/site-packages/kombu/serialization.py", line 50, in _reraise_errors
    yield
  File "/usr/local/lib/python3.6/site-packages/kombu/serialization.py", line 221, in dumps
    payload = encoder(data)
  File "/usr/local/lib/python3.6/site-packages/kombu/utils/json.py", line 72, in dumps
    **dict(default_kwargs, **kwargs))
  File "/usr/local/lib/python3.6/json/__init__.py", line 238, in dumps
    **kw).encode(obj)
  File "/usr/local/lib/python3.6/json/encoder.py", line 199, in encode
    chunks = self.iterencode(o, _one_shot=True)
  File "/usr/local/lib/python3.6/json/encoder.py", line 257, in iterencode
    return _iterencode(o, 0)
  File "/usr/local/lib/python3.6/site-packages/kombu/utils/json.py", line 62, in default
    return super(JSONEncoder, self).default(o)
  File "/usr/local/lib/python3.6/json/encoder.py", line 180, in default
    o.__class__.__name__)
TypeError: Object of type 'Upload' is not JSON serializable

During handling of the above exception, another exception occurred:

Traceback (most recent call last):
  File "/tE-backend/tRecorderApi/api/tests/tests_upload.py", line 27, in test_upload_zip_
    resp, stat = up.upload(file_to_upload)
  File "/tE-backend/tRecorderApi/api/file_transfer/Upload.py", line 14, in upload
    extract_and_save_project.delay(self, file, directory)
  File "/usr/local/lib/python3.6/site-packages/celery/app/task.py", line 413, in delay
    return self.apply_async(args, kwargs)
  File "/usr/local/lib/python3.6/site-packages/celery/app/task.py", line 536, in apply_async
    **options
  File "/usr/local/lib/python3.6/site-packages/celery/app/base.py", line 737, in send_task
    amqp.send_task_message(P, name, message, **options)
  File "/usr/local/lib/python3.6/site-packages/celery/app/amqp.py", line 554, in send_task_message
    **properties
  File "/usr/local/lib/python3.6/site-packages/kombu/messaging.py", line 169, in publish
    compression, headers)
  File "/usr/local/lib/python3.6/site-packages/kombu/messaging.py", line 252, in _prepare
    body) = dumps(body, serializer=serializer)
  File "/usr/local/lib/python3.6/site-packages/kombu/serialization.py", line 221, in dumps
    payload = encoder(data)
  File "/usr/local/lib/python3.6/contextlib.py", line 99, in __exit__
    self.gen.throw(type, value, traceback)
  File "/usr/local/lib/python3.6/site-packages/kombu/serialization.py", line 54, in _reraise_errors
    reraise(wrapper, wrapper(exc), sys.exc_info()[2])
  File "/usr/local/lib/python3.6/site-packages/vine/five.py", line 178, in reraise
    raise value.with_traceback(tb)
  File "/usr/local/lib/python3.6/site-packages/kombu/serialization.py", line 50, in _reraise_errors
    yield
  File "/usr/local/lib/python3.6/site-packages/kombu/serialization.py", line 221, in dumps
    payload = encoder(data)
  File "/usr/local/lib/python3.6/site-packages/kombu/utils/json.py", line 72, in dumps
    **dict(default_kwargs, **kwargs))
  File "/usr/local/lib/python3.6/json/__init__.py", line 238, in dumps
    **kw).encode(obj)
  File "/usr/local/lib/python3.6/json/encoder.py", line 199, in encode
    chunks = self.iterencode(o, _one_shot=True)
  File "/usr/local/lib/python3.6/json/encoder.py", line 257, in iterencode
    return _iterencode(o, 0)
  File "/usr/local/lib/python3.6/site-packages/kombu/utils/json.py", line 62, in default
    return super(JSONEncoder, self).default(o)
  File "/usr/local/lib/python3.6/json/encoder.py", line 180, in default
    o.__class__.__name__)
kombu.exceptions.EncodeError: Object of type 'Upload' is not JSON serializable
</error></testcase></testsuite>